Workbook

Sheet Synthèse
E3: SYNTHESE NUMERIQUE
A5: N° | B5: Domaines | C5: Total OUI | D5: Total NON | E5: Total PAS | F5: Total | G5: Score
A6: 1 | B6: Application en service | C6: =COUNTIF('4.1'!J2:J147,"OUI") -> 84 | D6: =COUNTIF('4.1'!J2:J147,"NON") -> 3 | E6: =COUNTIF('4.1'!J2:J147,"PAS") -> 59 | F6: =SUM(C6:E6) -> 146 | G6: =D6/F6 -> 0.020547945
A7: 2 | B7: Fonction informatique | C7: =COUNTIF('4.2'!F2:F141,"OUI") -> 74 | D7: =COUNTIF('4.2'!F2:F141,"NON") -> 8 | E7: =COUNTIF('4.2'!F2:F141,"PAS") -> 58 | F7: =SUM(C7:E7) -> 140 | G7: =D7/F7 -> 0.057142857
A8: 3 | B8: Projet informatique | C8: =COUNTIF('4.3'!F2:F476,"OUI") -> 339 | D8: =COUNTIF('4.3'!F2:F476,"NON") -> 63 | E8: =COUNTIF('4.3'!F2:F476,"PAS") -> 73 | F8: =SUM(C8:E8) -> 475 | G8: =D8/F8 -> 0.13263158
A9: 4 | B9: SUPPORT UTILISATEUR ET GESTON DU PARC | C9: =COUNTIF('4.4'!F2:F121,"OUI") -> 79 | D9: =COUNTIF('4.4'!F2:F121,"NON") -> 9 | E9: =COUNTIF('4.4'!F2:F121,"PAS") -> 32 | F9: =SUM(C9:E9) -> 120 | G9: =D9/F9 -> 0.075
A10: 5 | B10: SECURITE INFORMATIQUE | C10: =COUNTIF('4.5'!F2:F286,"OUI") -> 137 | D10: =COUNTIF('4.5'!F2:F286,"NON") -> 38 | E10: =COUNTIF('4.5'!F2:F286,"PAS") -> 110 | F10: =SUM(C10:E10) -> 285 | G10: =D10/F10 -> 0.13333333
A11: TOTAL | C11: =SUM(C6:C10) -> 713 | D11: =SUM(D6:D10) -> 121 | E11: =SUM(E6:E10) -> 332 | F11: =SUM(F6:F10) -> 1166 | G11: =SUM(G6:G10) -> 0.41865571
C12: SYNTHESE GRAPHIQUE

Sheet Global

Sheet 4.1
A1: DOMAINES | B1: RESPONSABLES | C1: DUREE | D1: MOYENS POUR LA REALISATION | E1: PARTIE PRENANTES | F1: POINTS DE CONTRÔLE | G1: OBJECTIFS DE CONTRÔLE | H1: CRITERES D'EVALUATION | I1: QUESTIONS D'EVALUATION | J1: REPONSES | K1: DOCUMENTS REQUIS | L1: RISQUES | M1: CRITICITE | N1: CONSEQUENCES | O1: RECOMMANDATIONS
A2: Applications en services | F2: Organisation | G2: S’assurer de l’existence d'un comité informatique | H2: Existence d'un comité informatique ; | I2: Existe-t-il un comité informatique ? | J2: OUI | K2: Charte du comité informatique, comptes rendus des réunions du comité informatique | L2: Absence de comité ou comité inactif | M2: Élevé | N2: Décisions informatiques non alignées avec les besoins des utilisateurs et les objectifs stratégiques de l'institution. | O2: Mettre en place des ateliers réguliers avec les parties prenantes.
H3: Le Comité est présidé par le Directeur Général ; | I3: Le Comité est-il présidé par le directeur général? | J3: OUI | K3: Organigramme de l'entreprise, procès-verbaux des réunions du comité informatique | L3: Manque d'expertise technique du DG | M3: Élevé | N3: Manque de coordination et de communication entre les différentes directions utilisatrices concernant les applications. | O3: Instaurer des canaux de communication formels inter-départements.
H4: Les directions utilisatrices sont représentées au sein de ce Comité ; | I4: Les directions utilisatrices sont-elles représentées au sein de ce comité ? | J4: OUI | K4: Liste des membres du comité informatique, mandats de représentation | L4: Représentation insuffisante ou inefficace des directions utilisatrices | M4: Élevé | N4: Prise de décisions informatiques unilatérales par la direction générale, sans prise en compte des besoins des utilisateurs. | O4: Établir un comité consultatif incluant des représentants des utilisateurs ou syndicat.
H5: Les directions utilisatrices sont influentes au sein de ce Comité. | I5: Les directions utilisatrices sont-elles influentes au sein de ce Comité? | J5: PAS | K5: Procès-verbaux des réunions du comité informatique, sondages ou évaluations de l'efficacité du comité | L5: Objectifs divergents des directions utilisatrices et de la direction informatique | M5: Élevé | N5: Influence disproportionnée de certaines directions utilisatrices sur les décisions relatives aux applications, au détriment des autres. | O5: Créer un cadre de gouvernance équilibré.
H6: Fréquence régulière des réunions et existence de comptes rendus | I6: Quelle est la fréquence régulière des réunions et existe-t-il des comptes rendus? | J6: OUI | K6: Calendrier des réunions du comité informatique, modèle de compte rendu standardisé | L6: Réunions irrégulières ou comptes rendus incomplets | M6: Élevé | N6: Manque de suivi et de contrôle des décisions prises lors des réunions, absence de traçabilité. | O6: Mettre en place un système de documentation et de suivi.
G7: S’assurer de l’existence d'une politique relative aux applications | H7: Il existe une politique relative aux applications au sein de l'institution ; | I7: Existe-t-il une politique relative aux applications au sein de l'institution ? | J7: OUI | K7: Document de politique des applications, attestations de lecture et de compréhension de la politique | L7: Politique obsolète ou inadaptée aux nouvelles technologies | M7: Élevé | N7: Mise en place d'applications non conformes aux besoins des utilisateurs et aux objectifs de l'institution. | O7: Effectuer des analyses de besoins approfondies.
H8: La politique est connue des utilisateurs d'applications ; | I8: La politique est-elle connue des utilisateurs d'applications ? | J8: OUI | K8: Liste de diffusion de la politique, captures d'écran ou liens vers les supports de diffusion | L8: Manque de sensibilisation ou de formation des utilisateurs | M8: Élevé | N8: Méconnaissance des politiques relatives aux applications par les utilisateurs, non-respect des règles établies. | O8: Organiser des sessions de formation régulières.
H9: La politique est largement diffusée ; | I9: La politique est-elle largement diffusée ? | J9: OUI | K9: Registre des non-conformités et des actions correctives, rapports d'audit de conformité | L9: Méthodes de diffusion inefficaces | M9: Élevé | N9: Diffusion restreinte des politiques, manque de transparence et d'accessibilité. | O9: Publier les politiques sur une plateforme accessible.
H10: La politique est mise en œuvre ; | I10: La politique est-elle mise en œuvre ? | J10: OUI | K10: Tableau de correspondance entre la politique et les phases du cycle de vie, modèles de documents pour chaque phase du cycle de vie | L10: Manque de suivi et de contrôle de l'application de la politique | M10: Élevé | N10: Non-application des politiques, inefficacité des règles établies. | O10: Établir des mécanismes de contrôle pour assurer la conformité.
H11: La politique couvre l'ensemble du cycle de vie de l’application ; | I11: La politique couvre-t-elle l'ensemble du cycle de vie de l’application ? | J11: NON | K11: Description des rôles et responsabilités dans la politique ou les procédures, matrice RACI (Responsable, Approbateur, Consulté, Informé) | L11: Lacunes dans certaines phases du cycle de vie de l'application | M11: Élevé | N11: Applications obsolètes ou non adaptées aux besoins actuels, manque de maintenance. | O11: Mettre en place un programme de mise à jour régulière.
G12: S’assurer que les rôle et responsabilités des utilisateurs sont bien définis | H12: Le rôle et les responsabilités des utilisateurs vis-à-vis de l’application sont clairement identifiés ; | I12: Le rôle et les responsabilités des utilisateurs vis-à-vis de l’application sont-ils clairement identifiés ? | J12: NON | K12: Procédure d'analyse des risques, modèles de rapports d'analyse des risques | L12: Ambiguïté des rôles et responsabilités des utilisateurs | M12: Élevé | N12: Mauvaise compréhension des rôles et responsabilités des utilisateurs, manque de clarté. | O12: Clarifier et documenter les rôles et responsabilités.
H13: Le rôle et les responsabilités des utilisateurs vis-à-vis de l’application couvrent l’analyse des risques ; | I13: Le rôle et les responsabilités des utilisateurs vis-à-vis de l’application couvrent-ils l’analyse des risques ? | J13: NON | K13: Procédure de définition des besoins de sécurité, modèles de cahiers des charges fonctionnels et techniques | L13: Manque de compétences des utilisateurs en matière d'analyse des risques | M13: Élevé | N13: Absence de prise en compte des risques liés à l'application par les utilisateurs, vulnérabilités non identifiées. | O13: Intégrer une évaluation des risques dans le développement.
H14: Le rôle et les responsabilités des utilisateurs vis-à-vis de l’application couvrent la définition des besoins de sécurité | I14: Le rôle et les responsabilités des utilisateurs vis-à-vis de l’application couvrent-ils la définition des besoins de sécurité? | J14: OUI | K14: Procédure de gestion des changements, registre des changements | L14: Sous-estimation des besoins de sécurité par les utilisateurs | M14: Élevé | N14: Non-respect des exigences de sécurité lors de la conception et du développement de l'application. | O14: Adopter des pratiques de développement sécurisé.
H15: Le rôle et les responsabilités des utilisateurs vis-à-vis de l’application couvrent la gestion des changements et des évolutions ; | I15: Le rôle et les responsabilités des utilisateurs vis-à-vis de l’application couvrent-ils la gestion des changements et des évolutions ? | J15: OUI | K15: Guides d'administration, procédure d'administration de l'application | L15: Manque de conscience des risques liés aux changements et évolutions | M15: Élevé | N15: Gestion inefficace des changements et évolutions de l'application, manque de flexibilité. | O15: Mettre en place une gestion des changements rigoureuse.
H16: Le rôle et les responsabilités des utilisateurs vis-à-vis de l’application couvrent l’administration de l’application. | I16: Le rôle et les responsabilités des utilisateurs vis-à-vis de l’application couvrent-ils l’administration de l’application? | J16: OUI | K16: Rapport d'analyse des risques, plan de traitement des risques | L16: Manque de compétences pour administrer l'application | M16: Élevé | N16: Administration déficiente de l'application, problèmes de performance et de disponibilité. | O16: Renforcer l'administration des systèmes.
G17: S’assurer qu’une analyse des risques a été réalisée | H17: Une analyse des risques spécifique à l’application a été réalisée ; | I17: Une analyse des risques spécifique à l’application a-t-elle été réalisée ? | J17: OUI | K17: Tableau de correspondance entre les risques et les besoins de sécurité, cahier des charges fonctionnel et technique | L17: Analyse des risques incomplète ou obsolète | M17: Élevé | N17: Identification insuffisante des risques spécifiques à l'application, vulnérabilités non détectées. | O17: Réaliser des audits de sécurité réguliers.
H18: L'analyse des risques a débouché sur la définition des besoins de sécurité. | I18: L'analyse des risques a-t-elle débouché sur la définition des besoins de sécurité? | J18: OUI | K18: Tableau de bord de suivi des performances, rapports d'analyse des performances | L18: Besoins de sécurité mal définis ou non appliqués | M18: Élevé | N18: Absence de définition des besoins de sécurité, manque de protection des données sensibles. | O18: Établir des exigences de sécurité claires.
H19: Monitoring des performances des services | I19: Y a-t-il un monitoring des performances des services? | J19: OUI | K19: Procédure de gestion des incidents, registre des incidents | L19: Surveillance insuffisante ou inefficace des performances des services | M19: Élevé | N19: Dégradation des performances de l'application, insatisfaction des utilisateurs. | O19: Mettre en place des indicateurs de performance.
H20: Gestion proactive des incidents et mise en place d’un support technique | I20: Y a -t-il une gestion proactive des incidents et mise en place d’un support technique? | J20: OUI | K20: Plan de reprise après sinistre, rapports de tests de reprise après sinistre | L20: Support technique insuffisant ou incompétent | M20: Moyen | N20: Incapacité à résoudre rapidement les incidents, manque de support technique. | O20: Renforcer l'équipe de support technique.
H21: Tests réguliers des procédures de reprise après sinistre | I21: Existe-t-il des tests réguliers des procédures de reprise après sinistre? | J21: PAS | K21: Planning du projet avec les dates des analyses, document de suivi des évolutions des besoins de sécurité | L21: Procédures de reprise après sinistre inefficaces ou non testées | M21: Moyen | N21: Difficultés à reprendre les activités après un sinistre, perte de données et d'informations. | O21: Élaborer un plan de continuité des activités.
G22: S’assurer que le prolongement de l'analyse de risque et de son expansion ont été réalisés | H22: Il y a eu un prolongement de l’analyse des risques et de l’expression des besoins de sécurité | I22: y a-t-il eu un prolongement de l’analyse des risques et de l’expression des besoins de sécurité? | J22: PAS | K22: Document du SLA, rapports de suivi du respect du SLA | L22: Analyse trop longue et besoins de sécurité évoluant plus vite que l'analyse | M22: Moyen | N22: Absence de prise en compte des risques et des besoins de sécurité lors des évolutions de l'application. | O22: Intégrer des évaluations de sécurité.
H23: Un contrat de service (SLA) entre l’informatique et la direction utilisatrice a été mis en œuvre. | I23: Un contrat de service (SLA) entre l’informatique et la direction utilisatrice at-il été mis en œuvre? | J23: PAS | K23: Procédure de journalisation, journaux de transactions | L23: SLA mal défini ou non respecté | M23: Moyen | N23: Non-respect des engagements contractuels, litiges potentiels. | O23: Établir des vérifications régulières de conformité.
H24: Journalisation et suivi des transactions inter-applicatives | I24: Y a-t-il la journalisation et le suivi des transactions inter-applicatives? | J24: PAS | K24: Rapports de tests de sécurité, documentation des mécanismes de chiffrement et d'authentification | L24: Journalisation insuffisante ou journaux non analysés | M24: Élevé | N24: Difficultés à suivre les transactions entre les applications, manque de visibilité. | O24: Mettre en place des outils d'analyse et de reporting.
H25: Vérification des mécanismes de chiffrement et d’authentification | I25: Les mécanismes de chiffrement et d’authentification sont-ils correctement mis en place et vérifiés ? | J25: PAS | K25: Rapports d'audit des interfaces, plan d'action suite aux audits | L25: Mécanismes de chiffrement et d'authentification obsolètes ou mal configurés | M25: Élevé | N25: Vulnérabilités liées aux mécanismes de chiffrement et d'authentification, risques de piratage. | O25: Utiliser des protocoles de sécurité robustes.
H26: Audit des interfaces d’échange de données | I26: Existe-t-il un audit des interfaces d’échange de données? | J26: PAS | K26: Documents de procédures internes, journaux d'activité | L26: Audits insuffisants ou non effectués régulièrement | M26: Élevé | N26: Difficultés à contrôler les échanges de données, risques de fuites d'informations sensibles. | O26: Implémenter des contrôles d'accès stricts.
F27: Application | G27: S'assurer que l'accès aux ressources de l'application (données et transactions) est restreint par un système de gestion d'accès | H27: Il y a une séparation des tâches au sein de la direction utilisatrice indépendamment de l’application ; | I27: Y a-t-il une séparation des tâches au sein de la direction utilisatrice indépendamment de l’application ? | J27: PAS | K27: Documents de procédures internes, journaux d'activité | L27: Manque de séparation des tâches dans la direction utilisatrice | M27: Élevé | N27: Risques d'erreurs et de fraudes liés à la concentration des tâches, manque de contrôle interne. | O27: Séparer les tâches critiques et renforcer les contrôles internes.
H28: Il y a une « maturité » de l’organisation vis-à-vis de ses systèmes d’information. | I28: l’organisation est-elle mature vis-à-vis de ses systèmes d’information? | J28: PAS | K28: Rapports de tests de sécurité, documentation des mécanismes de chiffrement et d'authentification | L28: Faible maturité organisationnelle vis-à-vis des systèmes d'information | M28: Élevé | N28: Manque d'adaptation aux évolutions technologiques, obsolescence des systèmes d'information. | O28: Évaluer régulièrement les technologies.
H29: Implémentation de mesures de chiffrement et de contrôle d’accès | I29: Existe-t-il une implémentation de mesures de chiffrement et de contrôle d’accès? | J29: PAS | K29: Rapports de tests de sécurité, documentation des mécanismes de chiffrement et d'authentification | L29: Absence de chiffrement et de contrôle d'accès | M29: Élevé | N29: Vulnérabilités liées aux accès non autorisés, risques de piratage. | O29: Renforcer les contrôles d'accès.
H30: Contrôle des accès aux données critiques | I30: Existe-t-il un *contrôle des accès aux données critiques? | J30: PAS | K30: Guides d'utilisation de l'application, manuels de formation | L30: Contrôle insuffisant des accès aux données critiques | M30: Élevé | N30: Accès non contrôlés aux données critiques, risques de fuites d'informations sensibles. | O30: Mettre en place des audits réguliers.
H31: Surveillance en temps réel des accès et détection des comportements anormaux | I31: y a-t-il une surveillance en temps réel des accès et détection des comportements anormaux? | J31: OUI | K31: Manuels de formation à l'application, registres de mise à jour des manuels | L31: Surveillance en temps réel des accès et détection de comportements anormaux inexistantes | M31: Élevé | N31: Difficultés à détecter les comportements anormaux, risques de piratage et de fraudes. | O31: Utiliser des outils de surveillance.
G32: S’assurer qu’une procédure de gestion des profils utilisateurs existe | H32: Un ou des manuels pour l’application existe ; | I32: Existe-t-il un ou des manuels pour l’application ? | J32: PAS | K32: Manuels de formation, registres de compétences des utilisateurs | L32: Documentation utilisateur (manuels) manquante ou obsolète | M32: Élevé | N32: Difficultés à utiliser l'application, manque d'autonomie des utilisateurs. | O32: Offrir des formations et des ressources d'apprentissage.
H33: Le manuel est à jour ; | I33: Le manuel est-il à jour ? | J33: PAS | K33: Manuels de formation, guides d'utilisation de l'application | L33: Manuel utilisateur non maîtrisé | M33: Élevé | N33: Informations obsolètes ou incorrectes, risques d'erreurs d'utilisation. | O33: Mettre à jour régulièrement les données.
H34: Le manuel est maitrisé | I34: Le manuel est-il maitrisé? | J34: PAS | K34: Manuels de formation, guides d'administration de l'application | L34: Absence de mode d'emploi dans le manuel | M34: Élevé | N34: Difficultés à comprendre le fonctionnement de l'application, manque d'efficacité. | O34: Fournir des manuels d'utilisation clairs.
H35: Le manuel comprend un mode d'emploi ; | I35: Le manuel comprend-il un mode d'emploi ? | J35: PAS | K35: Procédures de gestion des changements, registres de changements | L35: Manque de documentation sur le module d'administration | M35: Élevé | N35: Difficultés à résoudre les problèmes techniques, dépendance excessive du support informatique. | O35: Créer une base de connaissances.
H36: Le manuel comprend une présentation du module d’administration de l’application ; | I36: Le manuel comprend-il une présentation du module d’administration de l’application ? | J36: PAS | K36: Procédures de gestion des changements, registres de changements | L36: Absence de procédures formalisées pour les changements sur les programmes | M36: Élevé | N36: Difficultés à administrer l'application, manque de contrôle. | O36: Renforcer les processus d'administration.
G37: Vérifier que l’identification des utilisateurs est réalisée | H37: Des procédures formalisées imposant l’accord du « propriétaire » de l’application pour tout changement sur les programmes de l’application existent ; | I37: Des procédures formalisées imposant l’accord du « propriétaire » de l’application pour tout changement sur les programmes de l’application existent-ils? | J37: PAS | K37: Procédures de gestion des changements, registres de changements | L37: Absence de procédures formalisées pour les changements sur la planification | M37: Élevé | N37: Modifications non autorisées des programmes, risques d'erreurs et de fraudes. | O37: Mettre en place un suivi rigoureux des modifications.
H38: Des procédures formalisées imposant l’accord du « propriétaire » de l’application pour tout changement sur la planification des traitements informatiques existent ; | I38: Des procédures formalisées imposant l’accord du « propriétaire » de l’application pour tout changement sur la planification des traitements informatiques existent-ils ? | J38: PAS | K38: Guides d'administration de l'application, registres d'administration | L38: Absence de procédures formalisées pour les changements sur l'environnement technique | M38: Moyen | N38: Planification des tâches non maîtrisée, risques de retards et de dysfonctionnements. | O38: Utiliser des outils de gestion de projet.
H39: Des procédures formalisées imposant l’accord du « propriétaire » de l’application pour tout changement sur l’environnement technologique de l’application existent ; | I39: Des procédures formalisées imposant l’accord du « propriétaire » de l’application pour tout changement sur l’environnement technologique de l’application existent-ils? | J39: PAS | K39: Matrice RACI (Responsable, Approbateur, Consulté, Informé), registres d'habilitation | L39: Administration de l'application non assurée par les utilisateurs | M39: Moyen | N39: Paramétrage incorrect de l'environnement technique, risques de dysfonctionnements. | O39: Établir des procédures de configuration standardisées.
H40: L'administration est bien assurée par les utilisateurs. | I40: L'administration est-elle bien assurée par les utilisateurs? | J40: OUI | K40: Rapports de performance de l'application, tableau de bord de suivi des performances | L40: Droits d'accès mal attribués ou non limités | M40: Moyen | N40: Difficultés à utiliser l'application, manque d'autonomie des utilisateurs. | O40: Offrir des formations continues.
...

Sheet 4.2
A1: Domaines | B1: Points de Contrôle | C1: Objectifs de contrôle | D1: Critères d’évaluation | E1: Question d’Évaluation | F1: Réponses | G1: Documents Requis | H1: Risques | I1: Criticité | J1: Conséquences | K1: Recommandations
A2: FONCTION INFORMATIQUE | B2: Rôle et positionnement de l'informatique dans l'organisation | C2: Vérifier qu’ont été créés des Comités « informatique » (stratégique, pilotage,..) regroupant les différentes directions de l’Organisation en charge de recenser les besoins et les opportunités, gérer les priorités et suivre les projets | D2: Présence d’un Comité Informatique | E2: Le Comité Informatique est-il formellement mis en place ? | F2: NON | G2: Procès-verbal de création du comité, Charte de fonctionnement | H2: Manque de pilotage stratégique du SI | I2: Elevée | J2: Investissements non alignés avec les objectifs. | K2: Élaborer un plan stratégique SI en concertation avec les métiers.
D3: Fréquence des réunions | E3: Les réunions du Comité Informatique se tiennent-elles régulièrement ? | F3: OUI | G3: Calendrier annuel des réunions, Archives des comptes-rendus | H3: Perte de réactivité dans la prise de décision | I3: Moyenne | J3: Opportunités manquées et perte d'avantage concurrentiel. | K3: Mettre en place un processus de décision agile et transparent.
D4: Documentation des décisions | E4: Les décisions prises lors des réunions sont-elles systématiquement documentées ? | F4: PAS | G4: Registre des décisions, Comptes-rendus signés | H4: Absence de traçabilité des décisions | I4: Faible | J4: Difficulté à justifier les choix et à tirer des leçons des erreurs. | K4: Documenter systématiquement les décisions et les justifications.
D5: Mécanismes de suivi des projets | E5: Des mécanismes de suivi des projets informatiques sont-ils en place ? | F5: OUI | G5: Dashboard de suivi, Rapports d'avancement mensuels | H5: Dérive des délais, des coûts ou de la qualité | I5: Moyenne | J5: Dépassements budgétaires et insatisfaction des utilisateurs. | K5: Mettre en place un suivi rigoureux des projets et des indicateurs de performance.
D6: Implication des directions métiers | E6: Les directions métiers sont-elles impliquées dans les projets informatiques ? | F6: NON | G6: PV de réunions métiers, Lettres de mission des sponsors | H6: Solutions SI inadaptées aux besoins métiers | I6: Faible | J6: Faible adoption des outils et perte de productivité. | K6: Impliquer les utilisateurs métiers dès la conception des solutions.
C7: Vérifier l’existence d’une charte informatique ou de tout autre document définissant le rôle et le périmètre de responsabilité de la DSI | D7: Existence d’un document formalisé | E7: Un document formalisé sur la gouvernance SI existe-t-il ? | F7: OUI | G7: Politique de gouvernance SI, Procédure de validation | H7: Incohérences ou flou organisationnel | I7: Elevée | J7: Doublons de tâches et perte d'efficacité. | K7: Clarifier les rôles et responsabilités de chacun.
D8: Clarté des rôles de la DSI | E8: Les rôles et responsabilités de la DSI sont-ils clairement définis ? | F8: OUI | G8: Organigramme fonctionnel, Fiches de poste | H8: Conflits ou doublons de responsabilités | I8: Moyenne | J8: Tension et retards dans les projets. | K8: Définir les responsabilités et mettre en place des instances de coordination.
D9: Validation par la direction | E9: Ce document a-t-il été validé par la direction générale ? | F9: OUI | G9: PV de validation COMEX, Notes de validation officielles | H9: Projets validés sans alignement stratégique | I9: Faible | J9: Gaspillage de ressources et manque de valeur ajoutée. | K9: Évaluer systématiquement l'alignement stratégique des projets.
D10: Communication du document | E10: Le document de gouvernance est-il communiqué à l’ensemble des parties concernées ? | F10: OUI | G10: Plan de diffusion, Accusés de réception | H10: Incompréhension des orientations SI | I10: Moyenne | J10: Résistance au changement et difficultés de mise en œuvre. | K10: Communiquer clairement les orientations SI et impliquer les équipes.
D11: Mise à jour régulière | E11: Ce document est-il mis à jour régulièrement ? | F11: OUI | G11: Journal des modifications, Historique des versions | H11: Obsolescence des règles suivies | I11: Faible | J11: Non-conformité et vulnérabilités de sécurité. | K11: Mettre en place une veille réglementaire et technologique.
C12: Évaluer le degré d’implication et de maîtrise des organes de gestion dans les systèmes d’information de l’Organisation | D12: Niveau de participation des dirigeants | E12: Les dirigeants participent-ils activement à la gouvernance des systèmes d'information ? | F12: PAS | G12: Listes de présence aux réunions, PV de décisions stratégiques | H12: Perte de légitimité du SI | I12: Elevée | J12: Difficulté à obtenir des budgets et à mener des projets. | K12: Démontrer la valeur ajoutée du SI à travers des projets concrets.
D13: Connaissance des enjeux des SI | E13: Les enjeux liés aux SI sont-ils bien connus par les dirigeants ? | F13: OUI | G13: Présentations stratégiques, Comptes-rendus de briefings | H13: Décisions inadaptées aux réalités techniques | I13: Moyenne | J13: Projets irréalistes et échecs techniques. | K13: Impliquer les experts techniques dans les décisions stratégiques.
D14: Utilisation des outils SI par la direction | E14: Les outils SI sont-ils effectivement utilisés par la direction ? | F14: OUI | G14: Logs d'accès, Rapports d'utilisation | H14: Frein à l’adoption des outils SI | I14: Elevée | J14: Sous-utilisation des outils et manque de retour sur investissement. | K14: Mettre en place un accompagnement au changement et une formation adaptée.
D15: Suivi des indicateurs de performance | E15: Les indicateurs de performance SI sont-ils suivis de manière régulière ? | F15: OUI | G15: Tableaux de bord, Rapports d'analyse trimestriels | H15: Absence d’alerte sur les dérives | I15: Elevée | J15: Problèmes non résolus et pertes financières. | K15: Mettre en place un système d'alerte et de reporting.
D16: Feedback sur la gouvernance des SI | E16: La gouvernance des SI fait-elle l’objet d’un retour d’expérience ou d’un feedback structuré ? | F16: OUI | G16: Enquêtes de satisfaction, Rapports d'audit | H16: Gouvernance inefficace | I16: Moyenne | J16: Manque de pilotage et décisions incohérentes. | K16: Définir les rôles et responsabilités de la gouvernance.
C17: Vérifier en pratique que le leadership des grands projets est assuré par les organes de gestion | D17: Nomination d’un sponsor de projet | E17: Un sponsor de projet est-il systématiquement nommé pour chaque projet SI ? | F17: PAS | G17: Désignation officielle, PV de lancement | H17: Manque de leadership sur les projets | I17: Moyenne | J17: Projets qui s'éternisent et n'atteignent pas leurs objectifs. | K17: Désigner des chefs de projet compétents et leur donner les moyens de réussir.
D18: Suivi actif des projets par la direction | E18: La direction suit-elle activement l’avancement des projets ? | F18: OUI | G18: Rapports de comité de pilotage, Plans d'actions | H18: Perte d’alignement avec la stratégie | I18: Elevée | J18: Actions SI qui ne contribuent pas aux objectifs de l'entreprise. | K18: Mettre en place des indicateurs de suivi de l'alignement stratégique.
D19: Prise de décision stratégique | E19: La direction prend-elle des décisions stratégiques en lien avec les SI ? | F19: OUI | G19: PV de COMEX, Feuilles de décision | H19: Immobilisme ou actions incohérentes | I19: Elevée | J19: Perte de compétitivité et opportunités manquées. | K19: Favoriser l'innovation et l'agilité.
D20: Projets alignés avec la stratégie de l’organisation | E20: Les projets sont-ils bien alignés avec la stratégie globale de l’organisation ? | F20: OUI | G20: Cartographie des projets, Business cases | H20: Investissements sans valeur ajoutée | I20: Faible | J20: Gaspillage de ressources et manque de retour sur investissement. | K20: Évaluer systématiquement la valeur ajoutée des investissements SI.
D21: Ressources allouées adéquatement | E21: Les ressources nécessaires aux projets sont-elles allouées de manière adéquate ? | F21: OUI | G21: Budgets approuvés, Plans de charge | H21: Échec des projets par manque de moyens | I21: Faible | J21: Démotivation des équipes et perte de confiance. | K21: Allouer les ressources nécessaires aux projets et s'assurer de leur disponibilité.
C22: Vérifier que les métiers assurent leur rôle de MOA | D22: Désignation d’un responsable MOA | E22: Un responsable MOA est-il désigné pour piloter les projets métiers ? | F22: OUI | G22: Fiche de rôle MOA, PV de nomination | H22: Défaut de coordination métier-technique | I22: Elevée | J22: Solutions SI qui ne répondent pas aux besoins des utilisateurs. | K22: Mettre en place des instances de coordination entre les métiers et la DSI.
D23: Implication dans la définition des besoins | E23: Les directions métiers participent-elles à la définition des besoins ? | F23: NON | G23: Cahiers des charges, PV d'ateliers métiers | H23: Outils partiellement adaptés | I23: Moyenne | J23: Insatisfaction des utilisateurs et perte de productivité. | K23: Adapter les outils aux besoins spécifiques des utilisateurs.
D24: Validation des livrables | E24: Les livrables des projets sont-ils validés par les utilisateurs métiers ? | F24: NON | G24: Procès-verbaux de recette, Checklists de validation | H24: Mise en production non conforme | I24: Moyenne | J24: Incident de production et interruption de service. | K24: Mettre en place un processus de mise en production rigoureux.
D25: Formation des équipes métiers | E25: Les équipes métiers bénéficient-elles de formations adaptées aux solutions SI déployées ? | F25: NON | G25: Plans de formation, Évaluations post-formation | H25: Erreurs ou abandon des outils | I25: Moyenne | J25: Perte de données et retards dans les projets. | K25: Mettre en place des tests utilisateurs et un support technique efficace.
D26: Suivi de la satisfaction des utilisateurs | E26: La satisfaction des utilisateurs est-elle régulièrement mesurée et suivie ? | F26: OUI | G26: Enquêtes utilisateurs, Rapports de feedback | H26: Désengagement des utilisateurs | I26: Moyenne | J26: Faible adoption des outils et manque de retour sur investissement. | K26: Impliquer les utilisateurs dans le choix et la conception des outils.
B27: Planification stratégique | C27: Vérifier la couverture du périmètre fonctionnel | D27: Exhaustivité des fonctions couvertes | E27: L’ensemble des fonctions métiers est-il couvert par les solutions informatiques ? | F27: OUI | G27: PV de revues, Matrices RACI | H27: Solutions incomplètes | I27: Moyenne | J27: Insatisfaction des utilisateurs et manque de productivité. | K27: Définir les fonctionnalités attendues et s'assurer de leur réalisation.
D28: Validation des parties prenantes sur la couverture | E28: Les parties prenantes ont-elles validé la couverture fonctionnelle des systèmes ? | F28: OUI | G28: Études d'adéquation, Rapports d'analyse | H28: Blocages liés à des besoins non validés | I28: Moyenne | J28: Retards dans les projets et insatisfaction des utilisateurs. | K28: Mettre en place un processus de validation des besoins.
D29: Alignement avec les besoins métiers | E29: Les solutions mises en œuvre sont-elles bien alignées avec les besoins métiers ? | F29: OUI | G29: Registre des écarts, Plans de correction | H29: Retour sur investissement faible | I29: Moyenne | J29: Difficulté à justifier les investissements SI. | K29: Mettre en place un suivi du retour sur investissement des projets.
D30: Documentation des écarts éventuels | E30: Les écarts fonctionnels sont-ils documentés de manière formelle ? | F30: OUI | G30: Historique des mises à jour, Demandes de changement | H30: Non-identification des points critiques | I30: Elevée | J30: Problèmes non résolus et pertes financières. | K30: Mettre en place une analyse des risques et des points critiques.
D31: Mise à jour régulière selon les évolutions des besoins | E31: Les besoins sont-ils mis à jour régulièrement en fonction de leur évolution ? | F31: OUI | G31: Journal des modifications, Notes de version | H31: Outils mal alignés aux besoins actuels | I31: Elevée | J31: Perte de productivité et insatisfaction des utilisateurs. | K31: Adapter les outils aux besoins spécifiques des utilisateurs.
C32: Vérifier l’existence d’une analyse à jour des procédures de pilotage et de mise à jour du plan informatique | D32: Date de la dernière mise à jour | E32: La dernière mise à jour des besoins est-elle récente ? | F32: OUI | G32: Manuel des procédures, Guides opérationnels | H32: Utilisation de documents dépassés | I32: Elevée | J32: Erreurs et manque de productivité. | K32: Mettre en place une gestion documentaire efficace.
D33: Implication des parties prenantes dans l’analyse | E33: Les parties prenantes sont-elles impliquées dans l’analyse des besoins ? | F33: PAS | G33: Plans d'action, Rapports de suivi | H33: Sous-estimation des attentes réelles | I33: Elevée | J33: Solutions SI qui ne répondent pas aux besoins des utilisateurs. | K33: Impliquer les utilisateurs dans la définition des besoins.
D34: Formalisation des procédures documentées | E34: Les procédures de mise à jour sont-elles formalisées et documentées ? | F34: PAS | G34: Études d'impact, Mesures de performance | H34: Manque d'uniformité entraîne des erreurs. | I34: Elevée | J34: Données incohérentes et analyses erronées. | K34: Mettre en place des normes et des processus standardisés.
D35: Suivi de la mise en œuvre des actions identifiées | E35: Les actions identifiées lors de l’analyse sont-elles effectivement mises en œuvre et suivies ? | F35: PAS | G35: Registre de conformité, PV d'audits | H35: Retards compromettent les objectifs. | I35: Moyenne | J35: Manque de réactivité et opportunités manquées. | K35: Mettre en place une gestion de projet agile.
D36: Impact des mises à jour sur l’efficacité des processus | E36: Les documents sont-ils mis à jour conformément aux normes en vigueur ? | F36: PAS | G36: Inventaire des documents, Politique d'accès | H36: Mises à jour perturbent les opérations. | I36: Elevée | J36: Interruption de service et perte de productivité. | K36: Mettre en place un processus de mise à jour rigoureux.
C37: Vérifier l’existence des documents à jour d’urbanisme de l’Organisation | D37: Mise à jour des documents selon les normes en vigueur | E37: Les documents sont-ils accessibles aux parties prenantes concernées ? | F37: PAS | G37: Cartographie applicative, Schémas directeurs | H37: Non-conformité cause des sanctions. | I37: Elevée | J37: Amendes et perte de réputation. | K37: Mettre en place une veille réglementaire et un audit de conformité.
D38: Accessibilité des documents pour les parties prenantes | E38: Les documents sont-ils cohérents avec la stratégie d'urbanisme de l’organisation ? | F38: PAS | G38: PV de formations, Enquêtes d'adhésion | H38: Accès difficile freine la collaboration. | I38: Elevée | J38: Difficulté à justifier les choix et à tirer des leçons des erreurs. | K38: Documenter systématiquement les décisions et les justifications.
D39: Cohérence des documents avec la stratégie d'urbanisme | E39: Les équipes concernées se sont-elles approprié les documents d’urbanisme ? | F39: PAS | G39: Plans de revue, Feuilles de route | H39: Désalignement mène à des actions contradictoires. | I39: Moyenne | J39: Données incohérentes et analyses erronées. | K39: Mettre en place des normes et des processus standardisés.
D40: Appropriation des documents par les équipes concernées | E40: Les documents sont-ils révisés régulièrement en fonction des évolutions de l’organisation ? | F40: PAS | G40: Rapports d'analyse, Synthèses stratégiques | H40: Résistance limite l'efficacité. | I40: Elevée | J40: Dépassements budgétaires et insatisfaction des utilisateurs. | K40: Mettre en place un suivi rigoureux des projets et des indicateurs de performance.
...

Sheet 4.3
A1: Domaines | B1: Points de Contrôle | C1: Objectifs de contrôle | D1: Critères d’évaluation | E1: Question d’Évaluation | F1: Réponses | G1: Documents Requis | H1: Risques | I1: Criticité | J1: Conséquences | K1: Recommandations
A2: PROJET INFORMATQUE | B2: Objectifs et enjeux du projet | C2: S’assurer qu’une étude de la valeur et des études d'opportunité et d'impacts ont été réalisées | D2: Existence d’une étude de faisabilité documentée et validée | E2: Une étude de faisabilité a-t-elle été documentée et validée ? | F2: OUI | G2: Note de cadrage, Étude de faisabilité | H2: Mauvais cadrage du projet | I2: Moyenne | J2: Dérives budgétaires et retard important | K2: Élaborer une étude préalable approfondie avec validation directionnelle
D3: Analyse des opportunités et menaces associées réalisée et archivée | E3: L’analyse des opportunités et menaces associées a-t-elle été réalisée et archivée ? | F3: OUI | G3: Analyse SWOT, Rapport d’analyse stratégique | H3: Opportunités manquées | I3: Elevée | J3: Avantages potentiels non réalisés | K3: Mettre en place un processus formel d'identification des opportunités
D4: Prise en compte des impacts organisationnels et financiers évalués | E4: Les impacts organisationnels et financiers ont-ils été évalués et pris en compte ? | F4: OUI | G4: Étude d’impact, Étude financière | H4: Sous-estimation des coûts | I4: Elevée | J4: Dépenses imprévues impactant la rentabilité | K4: Réaliser une estimation détaillée avec buffer de sécurité (+20%)
D5: Consultation des parties prenantes attestée et rapportée | E5: La consultation des parties prenantes a-t-elle été attestée et rapportée ? | F5: NON | G5: Compte rendu de réunion, Feuille de présence | H5: Mauvaise adhésion des parties | I5: Faible | J5: Résistance au changement et échec d'adoption | K5: Impliquer les utilisateurs dès la phase de conception
C6: S’assurer qu’un bilan critique des processus existants a été effectué | D6: Décision formelle sur la pertinence du projet disponible | E6: Une décision formelle sur la pertinence du projet est-elle disponible ? | F6: OUI | G6: Décision de GO/NOGO, Compte rendu de comité | H6: Lancement d’un projet non pertinent | I6: Elevée | J6: Gaspillage de ressources sur des objectifs non stratégiques | K6: Aligner systématiquement les projets sur la roadmap stratégique
D7: Rapport d’analyse des processus actuels disponible et validé | E7: Un rapport d’analyse des processus actuels est-il disponible et validé ? | F7: PAS | G7: Rapport d’analyse des processus, Document de validation | H7: Solutions inadaptées | I7: Moyenne | J7: Solution ne répondant pas aux besoins | K7: Valider les spécifications via des prototypes et tests utilisateurs
D8: Identification des dysfonctionnements et points d’amélioration répertoriés | E8: Les dysfonctionnements et points d’amélioration ont-ils été identifiés et répertoriés ? | F8: OUI | G8: Liste des dysfonctionnements, Plan d’amélioration | H8: Pérennisation des erreurs | I8: Elevée | J8: Répétition des mêmes erreurs projet après projet | K8: Capitaliser les retours d'expérience dans un référentiel partagé
D9: Comparaison des performances actuelles avec des indicateurs de référence | E9: Les performances actuelles ont-elles été comparées à des indicateurs de référence ? | F9: PAS | G9: Rapport de comparaison, Tableau d’indicateurs | H9: Mauvaise mesure de performance | I9: Moyenne | J9: Impossibilité d'évaluer la réussite | K9: Définir des KPIs SMART avant le lancement
D10: Validation des conclusions du bilan par les instances de gouvernance | E10: Les conclusions du bilan ont-elles été validées par les instances de gouvernance ? | F10: OUI | G10: Procès-verbal de validation, Compte rendu de gouvernance | H10: Absence de soutien décisionnel | I10: Moyenne | J10: Prise de décision sans données fiables | K10: Implémenter des tableaux de bord décisionnels temps réel
C11: S’assurer que le choix de recourir à un nouveau système est obtenu après optimisation des processus concernés et vérification que cette optimisation ne suffit pas à apporter par elle-même les gains de performance attendus | D11: Documentation des processus cartographiée et mise à jour | E11: La documentation des processus a-t-elle été cartographiée et mise à jour ? | F11: OUI | G11: Cartographie des processus, Référentiel des procédures | H11: Incohérences fonctionnelles | I11: Elevée | J11: Incompatibilités techniques et dysfonctionnements | K11: Établir une architecture de référence contraignante
D12: Compte-rendu de l’optimisation des processus concernés établi | E12: Un compte-rendu de l’optimisation des processus concernés a-t-il été établi ? | F12: OUI | G12: Compte-rendu d’optimisation, Rapport d’audit | H12: Optimisation inefficace | I12: Moyenne | J12: Gains insuffisants par rapport aux coûts | K12: Prioriser les initiatives par analyse coûts/bénéfices
D13: Indicateurs de performance avant et après optimisation analysés | E13: Les indicateurs de performance avant et après optimisation ont-ils été analysés ? | F13: PAS | G13: Rapport d’indicateurs, Tableau comparatif | H13: Impact non mesuré | I13: Moyenne | J13: Impacts réels inconnus | K13: Prévoir un plan de mesure d'impact post-déploiement
D14: Justification technique et économique de l’abandon d’une simple amélioration disponible | E14: La justification technique et économique de l’abandon d’une simple amélioration est-elle disponible ? | F14: OUI | G14: Rapport d’évaluation, Analyse économique | H14: Investissements injustifiés | I14: Moyenne | J14: Dépenses sans retour sur investissement | K14: Exiger une business case validée par la direction financière
D15: Évaluation des gains obtenus par optimisation seule insuffisants formalisée | E15: Les gains obtenus par l’optimisation seule ont-ils été évalués et jugés insuffisants ? | F15: OUI | G15: Document comparatif, Étude de faisabilité | H15: Solution non optimale retenue | I15: Moyenne | J15: Choix sous-optimal pénalisant l'organisation | K15: Appliquer une méthode multicritère de sélection rigoureuse
C16: S’assure que les objectifs et périmètres du projet sont définis, partagés et stabilisés | D16: Analyse comparative entre optimisation et solution nouvelle réalisée | E16: Une analyse comparative entre optimisation et solution nouvelle a-t-elle été réalisée ? | F16: OUI | G16: Document de cadrage, Note de lancement | H16: Objectifs flous | I16: Moyenne | J16: Incompréhension des attentes | K16: Formaliser un document d'orientation projet signé par toutes les parties
D17: Document de cadrage du projet rédigé et diffusé | E17: Le document de cadrage du projet a-t-il été rédigé et diffusé ? | F17: OUI | G17: Objectifs validés, Feuille de route | H17: Dérive des livrables | I17: Elevée | J17: Livraisons ne correspondant pas aux attentes | K17: Mettre en place des jalons de validation intermédiaires
D18: Objectifs mesurables, atteignables et datés validés par la direction | E18: Les objectifs ont-ils été mesurables, atteignables et validés par la direction ? | F18: NON | G18: Document de périmètre, Cahier des charges | H18: Travaux hors périmètre | I18: Faible | J18: Augmentation non maîtrisée des coûts | K18: Instaurer un strict contrôle du périmètre et processus de changement
D19: Définition claire des périmètres fonctionnels et techniques actée | E19: La définition des périmètres fonctionnels et techniques a-t-elle été clairement actée ? | F19: OUI | G19: Actes de validation, Relevés de décisions | H19: Non-alignement stratégique | I19: Faible | J19: Projet devenu obsolète ou inutile | K19: Réaliser des points d'alignement stratégique trimestriels
D20: Actes de validation et de partage des objectifs accessibles | E20: Les actes de validation et de partage des objectifs sont-ils accessibles ? | F20: OUI | G20: Plan de gestion des risques, Tableau de contraintes | H20: Ignorance des risques majeurs | I20: Moyenne | J20: Surprise par des problèmes majeurs | K20: Effectuer une analyse de risques approfondie en amont
C21: S’assurer que les principales orientations du système cible ont été explicitées | D21: Prise en compte des contraintes et risques identifiés | E21: Les contraintes et risques identifiés ont-ils été pris en compte ? | F21: OUI | G21: Spécifications techniques, Schémas fonctionnels | H21: Solution mal adaptée | I21: Moyenne | J21: Solution technique inappropriée | K21: Valider les choix techniques par un comité d'experts indépendants
D22: Description fonctionnelle et technique du système cible disponible | E22: La description fonctionnelle et technique du système cible est-elle disponible ? | F22: OUI | G22: Comparatif technologique, Compte rendu d’arbitrage | H22: Choix technique contesté | I22: Elevée | J22: Conflits et rejet de la solution | K22: Organiser des preuves de concept avant sélection finale
D23: Options technologiques étudiées et arbitrages justifiés | E23: Les options technologiques ont-elles été étudiées et les arbitrages justifiés ? | F23: OUI | G23: Document d’architecture, Note d’intégration | H23: Incompatibilité avec l’existant | I23: Moyenne | J23: Problèmes d'interfaçage et de compatibilité | K23: Élaborer une cartographie détaillée de l'existant
D24: Synthèse des choix d’architecture et d’intégration rédigée | E24: Une synthèse des choix d’architecture et d’intégration a-t-elle été rédigée ? | F24: PAS | G24: Compte rendu de validation, PV de comité | H24: Refus de mise en œuvre | I24: Moyenne | J24: Refus des équipes d'utiliser la solution | K24: Mener une campagne d'adhésion en amont avec les opérationnels
D25: Validation des orientations par les instances décisionnelles | E25: Les orientations ont-elles été validées par les instances décisionnelles ? | F25: OUI | G25: Étude d’impact, Analyse de compatibilité | H25: Défaillance en production | I25: Faible | J25: Incidents répétés en production | K25: Instaurer des environnements de pré-production et tests rigoureux
C26: S’assurer que les principaux acteurs sont identifiés | D26: Analyse d’impacts et de compatibilité réalisée | E26: Une analyse d’impacts et de compatibilité a-t-elle été réalisée ? | F26: OUI | G26: Liste des acteurs, Organigramme projet | H26: Responsabilités floues | I26: Moyenne | J26: Confusion dans l'exécution des tâches | K26: Élaborer une matrice RACI détaillée pour toutes les activités
D27: Liste nominative et rôle des acteurs recensés | E27: La liste nominative et le rôle des acteurs ont-ils été recensés ? | F27: OUI | G27: Registre des parties, Documents de validation | H27: Parties prenantes oubliées | I27: Moyenne | J27: Besoins spécifiques ignorés | K27: Identifier et consulter toutes les parties prenantes en amont
D28: Acteurs internes et externes intégrés et validés | E28: Les acteurs internes et externes ont-ils été intégrés et validés ? | F28: OUI | G28: Tableau des responsabilités, RACI | H28: Conflits de rôles | I28: Elevée | J28: Conflits d'intérêts et chevauchements | K28: Clarifier les rôles et responsabilités dans une charte projet
D29: Tableau de répartition des responsabilités établi | E29: Un tableau de répartition des responsabilités a-t-il été établi ? | F29: PAS | G29: Feuilles de présence, Comptes rendus | H29: Engagement non vérifié | I29: Moyenne | J29: Engagements non tenus | K29: Mettre en place un suivi formel des engagements avec compte-rendu
D30: Actes de participation et comptes rendus des réunions disponibles | E30: Les actes de participation et les comptes rendus des réunions sont-ils disponibles ? | F30: OUI | G30: Cartographie des acteurs, Registre des parties | H30: Manque d’alignement | I30: Moyenne | J30: Objectifs divergents entre équipes | K30: Organiser des ateliers d'alignement inter-services
B31: Étude d'opportunité et expression des besoins | C31: S’assurer que l'expression détaillée des besoins est formalisée dans un cahier des charges fait par la MOA | D31: Cartographie des parties prenantes mise à jour | E31: La cartographie des parties prenantes a-t-elle été mise à jour ? | F31: OUI | G31: Fiche de recueil des besoins, Questionnaire utilisateurs | H31: Besoins mal identifiés | I31: Moyenne | J31: Solution ne répondant pas aux attentes | K31: Formaliser un cahier des charges exhaustif et validé
D32: Recueil formalisé des besoins utilisateurs validé | E32: Le recueil des besoins utilisateurs a-t-il été formalisé et validé ? | F32: OUI | G32: Fiches de recueil des besoins, Procès-verbal de validation des besoins | H32: Inadéquation entre les besoins réels et la solution livrée | I32: Elevée | J32: Écart entre ce qui est livré et ce qui est attendu | K32: Impliquer régulièrement le maître d'ouvrage dans les validations
D33: Cahier des charges structuré et signé par la MOA | E33: Le cahier des charges a-t-il été structuré et signé par la MOA ? | F33: OUI | G33: Cahier des charges complet, Signature de la MOA | H33: Non-alignement du projet avec les attentes du maître d’ouvrage | I33: Moyenne | J33: Perte de vue des objectifs initiaux | K33: Référencer systématiquement aux documents initiaux dans les revues
D34: Traçabilité des besoins vers les exigences fonctionnelles assurée | E34: La traçabilité des besoins vers les exigences fonctionnelles est-elle assurée ? | F34: OUI | G34: Cahier des charges, Matrice de traçabilité des exigences | H34: Perte de lien entre besoins initiaux et développement | I34: Moyenne | J34: Ressources insuffisantes ou délais irréalistes | K34: Appliquer une méthode de planification rigoureuse (type PERT)
D35: Priorisation des besoins justifiée et documentée | E35: La priorisation des besoins a-t-elle été justifiée et documentée ? | F35: PAS | G35: Document de priorisation, Justificatif de classement | H35: Mauvaise allocation des ressources ou délais mal évalués | I35: Moyenne | J35: Conflits sur la finalité du projet | K35: Documenter et faire valider les objectifs par toutes les parties
C36: S’assurer que le cahier des charges préconise une solution fonctionnellement et techniquement pertinente au regard des besoins exprimés | D36: Validation conjointe MOA et parties prenantes attestée | E36: La validation conjointe de la MOA et des parties prenantes a-t-elle été attestée ? | F36: PAS | G36: PV de réunion de validation, Signatures MOA et parties prenantes | H36: Désaccords ultérieurs sur les objectifs du projet | I36: Moyenne | J36: Incompréhension des besoins réels | K36: Organiser des ateliers de conception collaboratifs
D37: Cahier des charges comportant les exigences fonctionnelles et techniques détaillées | E37: Le cahier des charges comporte-t-il les exigences fonctionnelles et techniques détaillées ? | F37: PAS | G37: Cahier des charges détaillé, Annexe technique fonctionnelle | H37: Spécifications insuffisantes ou mal interprétées | I37: Moyenne | J37: Solution technique inadaptée aux usages | K37: Privilégier les approches user-centric design
D38: Adéquation entre besoins exprimés et solution proposée vérifiée | E38: L’adéquation entre les besoins exprimés et la solution proposée a-t-elle été vérifiée ? | F38: PAS | G38: Matrice de validation, Rapport d’évaluation de conformité | H38: Conception d'une solution inadaptée | I38: Moyenne | J38: ROI négatif ou insuffisant | K38: Réaliser une analyse financière approfondie en amont
D39: Analyse comparative des solutions candidates effectuée | E39: Une analyse comparative des solutions candidates a-t-elle été effectuée ? | F39: PAS | G39: Tableau comparatif des solutions, Rapport d’analyse multicritère | H39: Choix d’une solution inefficace ou coûteuse | I39: Moyenne | J39: Problèmes juridiques ou techniques imprévus | K39: Effectuer une revue légale et technique complète
D40: Solution retenue validée au regard des performances attendues | E40: La solution retenue a-t-elle été validée au regard des performances attendues ? | F40: PAS | G40: PV de validation de la solution, Rapport de tests de performance | H40: Mauvais retour sur investissement | I40: Moyenne | J40: Besoins d'utilisateurs clés ignorés | K40: Cartographier l'ensemble des personas utilisateurs
...

Sheet 4.4
A1: Domaines | B1: Points de Contrôle | C1: Objectifs de contrôle | D1: Critères d’évaluation | E1: Question d’Évaluation | F1: Réponses | G1: Documents Requis | H1: Risques | I1: Criticité | J1: Conséquences | K1: Recommandations
A2: SUPPORT UTILISATEUR ET GESTON DU PARC | B2: Fonction support : audit fiabilité et sécurité | C2: S’assurer qu’une structure de centre d’assistance (help-desk) (HD) est mise en place | D2: Existence d’une organisation dédiée avec des ressources identifiées | E2: Existe-t-il une organisation dédiée avec des ressources identifiées ? | F2: OUI | G2: Organigramme du centre d'assistance, Plan de gestion des ressources humaines du HD | H2: Absence de cadre organisationnel structuré | I2: Elevée | J2: Délais de traitement allongés et insatisfaction des utilisateurs | K2: Élaborer un organigramme fonctionnel avec fiches de poste détaillées
D3: Nomination d’un responsable du centre d’assistance | E3: Un responsable du centre d’assistance a-t-il été nommé ? | F3: NON | G3: Acte de nomination du responsable du centre d’assistance, Description de poste du responsable du centre d’assistance | H3: Dilution des responsabilités opérationnelles | I3: Moyenne | J3: Confusion dans l'exécution des tâches critiques | K3: Établir une matrice RACI pour chaque processus clé
D4: Disponibilité d’un budget dédié au fonctionnement du HD | E4: Un budget spécifique est-il alloué au fonctionnement du HD ? | F4: OUI | G4: Budget annuel alloué au fonctionnement du HD, Plan de financement et prévisions budgétaires pour le HD | H4: Insuffisance budgétaire chronique | I4: Faible | J4: Dégradation progressive de la qualité de service | K4: Mettre en place une budgétisation basée sur les besoins réels
D5: Existence d’un local ou espace identifié pour le HD | E5: Un local ou un espace est-il identifié pour le HD ? | F5: OUI | G5: Plan d’aménagement des espaces du centre d’assistance, Contrat de location ou de mise à disposition des locaux | H5: Dispersion géographique des équipes | I5: Moyenne | J5: Inefficacité dans la coordination des interventions | K5: Déployer des outils collaboratifs unifiés et standardisés
D6: Niveau de service défini et formalisé | E6: Un niveau de service est-il défini et formalisé ? | F6: OUI | G6: Document de définition des niveaux de service (SLA), Accord de niveau de service signé avec les parties prenantes | H6: Définition floue des engagements de service | I6: Faible | J6: Attentes divergentes entre parties prenantes | K6: Formaliser un SLA avec indicateurs mesurables et validés
C7: S’assurer qu’une procédure de gestion des demandes d’assistance est diffusée et connue des utilisateurs | D7: Existence d’un document formalisé de procédure | E7: Un document de procédure est-il formalisé ? | F7: OUI | G7: Manuel des procédures opérationnelles du HD, Document de procédures d'assistance utilisateur | H7: Improvisation des processus de support | I7: Elevée | J7: Incohérence dans les traitements des demandes | K7: Documenter les procédures dans un référentiel unique
D8: Communication de la procédure à tous les utilisateurs | E8: La procédure est-elle communiquée à tous les utilisateurs ? | F8: NON | G8: Email de communication de la procédure aux utilisateurs, Affiche ou notice informant les utilisateurs de la procédure | H8: Méconnaissance des procédures par les utilisateurs | I8: Moyenne | J8: Non-respect systématique des processus | K8: Lancer des campagnes de sensibilisation ciblées
D9: Accessibilité de la procédure via l’intranet ou support papier | E9: La procédure est-elle accessible via l’intranet ou un support papier ? | F9: OUI | G9: Page intranet dédiée aux procédures du HD, Brochure papier des procédures du centre d’assistance | H9: Difficulté d'accès aux référentiels | I9: Elevée | J9: Difficultés à trouver l'information nécessaire | K9: Centraliser les documents dans un portail unique et intuitif
D10: Mises à jour régulières du document | E10: Le document de procédure est-il mis à jour régulièrement ? | F10: PAS | G10: Registre des versions du document de procédure, Rapport de révision annuelle des procédures | H10: Application de procédures obsolètes | I10: Elevée | J10: Application de méthodes inadaptées | K10: Instaurer des revues trimestrielles des processus
D11: Validation de la procédure par la DSI | E11: La procédure a-t-elle été validée par la DSI ? | F11: OUI | G11: Document de validation de la procédure par la DSI, Compte-rendu de la réunion de validation avec la DSI | H11: Désalignement avec la stratégie SI | I11: Elevée | J11: Conflits opérationnels récurrents | K11: Aligner les procédures avec la roadmap SI
C12: S’assurer qu’une procédure d'escalade mise en place | D12: Formalisme de la procédure d’escalade | E12: La procédure d’escalade est-elle formalisée ? | F12: PAS | G12: Document décrivant les étapes d’escalade des incidents, Schéma de procédure d’escalade avec les rôles et responsabilités | H12: Gestion réactive des urgences | I12: Elevée | J12: Aggravation des incidents critiques | K12: Formaliser des procédures d'urgence avec seuils d'activation
D13: Existence de paliers définis et rôles associés | E13: Des paliers d’escalade et les rôles associés sont-ils définis ? | F13: OUI | G13: Tableau récapitulatif des paliers d’escalade et des rôles associés, Description des responsabilités et actions à chaque palier d’escalade | H13: Flou dans la chaîne d'escalade | I13: Elevée | J13: Escalades inappropriées ou tardives | K13: Définir clairement les paliers et responsabilités
D14: Temps de réponse par niveau d’escalade | E14: Un temps de réponse est-il prévu pour chaque niveau d’escalade ? | F14: OUI | G14: Accord de niveau de service (SLA) avec les temps de réponse, Tableau de suivi des temps de réponse par niveau d’escalade | H14: Dépassement systématique des délais | I14: Elevée | J14: Détérioration de la relation utilisateur | K14: Implémenter des outils de suivi des délais avec alertes
